<mujoco model="g1_23dof">
    <compiler angle="radian" meshdir="../meshes/g1"/>

    <default>
        <default class="g1">
            <geom contype="0" conaffinity="0"/>
            <joint frictionloss="0.1" solimplimit="0.97 0.995 0.001"/>

            <default class="hip">
                <default class="hip_pitch">
                    <joint axis="0 1 0" range="-2.5307 2.8798" actuatorfrcrange="-88 88" armature="0.01017752004"/>
                </default>
                <default class="hip_roll">
                    <joint axis="1 0 0" actuatorfrcrange="-139 139" armature="0.025101925"/>
                </default>
                <default class="hip_yaw">
                    <joint axis="0 0 1" range="-2.7576 2.7576" actuatorfrcrange="-88 88" armature="0.01017752004"/>
                </default>
            </default>
            <default class="knee">
                <joint axis="0 1 0" range="-0.087267 2.8798" actuatorfrcrange="-139 139" armature="0.025101925"/>
            </default>
            <default class="ankle">
                <default class="ankle_pitch">
                    <joint axis="0 1 0" range="-0.87267 0.5236" actuatorfrcrange="-50 50" armature="0.00721945"/>
                </default>
                <default class="ankle_roll">
                    <joint axis="1 0 0" range="-0.2618 0.2618" actuatorfrcrange="-50 50" armature="0.00721945"/>
                </default>
            </default>
            <default class="waist_yaw">
                <joint axis="0 0 1" range="-2.618 2.618" actuatorfrcrange="-88 88" armature="0.01017752004"/>
            </default>
            <default class="shoulder">
                <default class="shoulder_pitch">
                    <joint axis="0 1 0" range="-3.0892 2.6704" actuatorfrcrange="-25 25" armature="0.003609725"/>
                </default>
                <default class="shoulder_roll">
                    <joint axis="1 0 0" actuatorfrcrange="-25 25" armature="0.003609725"/>
                </default>
                <default class="shoulder_yaw">
                    <joint axis="0 0 1" range="-2.618 2.618" actuatorfrcrange="-25 25" armature="0.003609725"/>
                </default>
            </default>
            <default class="elbow">
                <joint axis="0 1 0" range="-1.0472 2.0944" actuatorfrcrange="-25 25" armature="0.003609725"/>
            </default>
            <default class="wrist_roll">
                <joint axis="1 0 0" range="-1.97222 1.97222" actuatorfrcrange="-25 25" armature="0.003609725"/>
            </default>

            <default class="visual">
                <geom group="2" type="mesh" density="0" material="silver"/>
            </default>
            <default class="collision">
                <geom group="3" rgba=".2 .6 .2 .3" contype="1" conaffinity="1"/>
            </default>
            <site group="5" rgba="1 0 0 1"/>
        </default>
    </default>

    <asset>
        <material name="silver" rgba="0.7 0.7 0.7 1"/>
        <material name="black" rgba="0.2 0.2 0.2 1"/>

        <mesh name="pelvis" file="pelvis.STL"/>
        <mesh name="pelvis_contour_link" file="pelvis_contour_link.STL"/>
        <mesh name="left_hip_pitch_link" file="left_hip_pitch_link.STL"/>
        <mesh name="left_hip_roll_link" file="left_hip_roll_link.STL"/>
        <mesh name="left_hip_yaw_link" file="left_hip_yaw_link.STL"/>
        <mesh name="left_knee_link" file="left_knee_link.STL"/>
        <mesh name="left_ankle_pitch_link" file="left_ankle_pitch_link.STL"/>
        <mesh name="left_ankle_roll_link" file="left_ankle_roll_link.STL"/>
        <mesh name="right_hip_pitch_link" file="right_hip_pitch_link.STL"/>
        <mesh name="right_hip_roll_link" file="right_hip_roll_link.STL"/>
        <mesh name="right_hip_yaw_link" file="right_hip_yaw_link.STL"/>
        <mesh name="right_knee_link" file="right_knee_link.STL"/>
        <mesh name="right_ankle_pitch_link" file="right_ankle_pitch_link.STL"/>
        <mesh name="right_ankle_roll_link" file="right_ankle_roll_link.STL"/>
        <mesh name="torso_link" file="torso_link.STL"/>
        <mesh name="logo_link" file="logo_link.STL"/>
        <mesh name="head_link" file="head_link.STL"/>
        <mesh name="waist_support_link" file="waist_support_link.STL"/>
        <mesh name="left_shoulder_pitch_link" file="left_shoulder_pitch_link.STL"/>
        <mesh name="left_shoulder_roll_link" file="left_shoulder_roll_link.STL"/>
        <mesh name="left_shoulder_yaw_link" file="left_shoulder_yaw_link.STL"/>
        <mesh name="left_elbow_link" file="left_elbow_link.STL"/>
        <mesh name="left_wrist_roll_rubber_hand" file="left_wrist_roll_rubber_hand.STL"/>
        <mesh name="right_shoulder_pitch_link" file="right_shoulder_pitch_link.STL"/>
        <mesh name="right_shoulder_roll_link" file="right_shoulder_roll_link.STL"/>
        <mesh name="right_shoulder_yaw_link" file="right_shoulder_yaw_link.STL"/>
        <mesh name="right_elbow_link" file="right_elbow_link.STL"/>
        <mesh name="right_wrist_roll_rubber_hand" file="right_wrist_roll_rubber_hand.STL"/>

        <texture type="skybox" builtin="gradient" rgb1="0.3 0.5 0.7" rgb2="0 0 0" width="512" height="3072"/>
        <texture type="2d" name="groundplane" builtin="checker" mark="edge" rgb1="0.2 0.3 0.4" rgb2="0.1 0.2 0.3"
                 markrgb="0.8 0.8 0.8" width="300" height="300"/>
        <material name="groundplane" texture="groundplane" texuniform="true" texrepeat="5 5" reflectance="0.2"/>
    </asset>

    <worldbody>
        <light pos="0 0 1.5" dir="0 0 -1" directional="true"/>
        <geom name="floor" size="0 0 0.01" type="plane" material="groundplane" conaffinity="1"/>

        <body name="pelvis" pos="0 0 0.793" childclass="g1">
            <inertial pos="0 0 -0.07605" quat="1 0 -0.000399148 0" mass="3.813" diaginertia="0.010549 0.0093089 0.0079184"/>
            <freejoint name="floating_base_joint"/>
            <geom class="visual" material="black" mesh="pelvis"/>
            <geom class="visual" mesh="pelvis_contour_link"/>
            <geom mesh="pelvis_contour_link" class="visual"/>
            <geom name="pelvis_collision" class="collision" type="sphere" size="0.07" pos="0 0 -0.08"/>
            <site name="imu_in_pelvis" size="0.01" pos="0.04525 0 -0.08339"/>
            <site name="pelvis" size="0.01" pos="0 0 0"/>

            <!-- LEFT LEG -->
            <body name="left_hip_pitch_link" pos="0 0.064452 -0.1027">
                <inertial pos="0.002741 0.047791 -0.02606" quat="0.954862 0.293964 0.0302556 0.030122" mass="1.35"
                          diaginertia="0.00181517 0.00153422 0.00116212"/>
                <joint name="left_hip_pitch_joint" class="hip_pitch"/>
                <geom class="visual" material="black" mesh="left_hip_pitch_link"/>
                <geom material="black" mesh="left_hip_pitch_link" class="visual"/>
                <body name="left_hip_roll_link" pos="0 0.052 -0.030465" quat="0.996179 0 -0.0873386 0">
                    <inertial pos="0.029812 -0.001045 -0.087934" quat="0.977808 -1.97119e-05 0.205576 -0.0403793" mass="1.52"
                              diaginertia="0.00254986 0.00241169 0.00148755"/>
                    <joint name="left_hip_roll_joint" class="hip_roll" range="-0.5236 2.9671"/>
                    <geom class="visual" mesh="left_hip_roll_link"/>
                    <geom mesh="left_hip_roll_link" class="visual"/>
                    <geom name="left_thigh" class="collision" type="capsule" size="0.05" fromto="0.02 0 0 0.02 0 -0.2"/>
                    <body name="left_hip_yaw_link" pos="0.025001 0 -0.12412">
                        <inertial pos="-0.057709 -0.010981 -0.15078" quat="0.600598 0.15832 0.223482 0.751181" mass="1.702"
                                  diaginertia="0.00776166 0.00717575 0.00160139"/>
                        <joint name="left_hip_yaw_joint" class="hip_yaw"/>
                        <geom class="visual" mesh="left_hip_yaw_link"/>
                        <body name="left_knee_link" pos="-0.078273 0.0021489 -0.17734" quat="0.996179 0 0.0873386 0">
                            <inertial pos="0.005457 0.003964 -0.12074" quat="0.923418 -0.0327699 0.0158246 0.382067" mass="1.932"
                                      diaginertia="0.0113804 0.0112778 0.00146458"/>
                            <joint name="left_knee_joint" class="knee"/>
                            <geom class="visual" mesh="left_knee_link"/>
                            <geom name="left_shin" class="collision" type="capsule" size="0.04" fromto="0.02 0 0 0.02 0 -0.25"/>
                            <body name="left_ankle_pitch_link" pos="0 -9.4445e-05 -0.30001">
                                <inertial pos="-0.007269 0 0.011137" quat="0.603053 0.369225 0.369225 0.603053" mass="0.074"
                                          diaginertia="1.89e-05 1.40805e-05 6.9195e-06"/>
                                <joint name="left_ankle_pitch_joint" class="ankle_pitch"/>
                                <geom class="visual" mesh="left_ankle_pitch_link"/>
                                <body name="left_ankle_roll_link" pos="0 0 -0.017558">
                                    <site name="left_foot" rgba="1 0 0 1"/>
                                    <inertial pos="0.026505 0 -0.016425" quat="-0.000481092 0.728482 -0.000618967 0.685065" mass="0.608"
                                              diaginertia="0.00167218 0.0016161 0.000217621"/>
                                    <joint name="left_ankle_roll_joint" class="ankle_roll"/>
                                    <geom class="visual" material="black" mesh="left_ankle_roll_link"/>
                                    <geom name="left_foot1_collision" type="capsule" size="0.01" class="collision" fromto="0.1 -0.026 -0.025 0.05 -0.027 -0.025"/>
                                    <geom name="left_foot2_collision" type="capsule" size="0.01" class="collision" fromto="-0.044 -0.018 -0.025 0.123 -0.018 -0.025"/>
                                    <geom name="left_foot3_collision" type="capsule" size="0.01" class="collision" fromto="-0.052 -0.01 -0.025 0.13 -0.01 -0.025"/>
                                    <geom name="left_foot4_collision" type="capsule" size="0.01" class="collision" fromto="-0.054 0 -0.025 0.132 0 -0.025"/>
                                    <geom name="left_foot5_collision" type="capsule" size="0.01" class="collision" fromto="-0.052 0.01 -0.025 0.13 0.01 -0.025"/>
                                    <geom name="left_foot6_collision" type="capsule" size="0.01" class="collision" fromto="-0.044 0.018 -0.025 0.123 0.018 -0.025"/>
                                    <geom name="left_foot7_collision" type="capsule" size="0.01" class="collision" fromto="0.1 0.026 -0.025 0.05 0.026 -0.025"/>
                                </body>
                            </body>
                        </body>
                    </body>
                </body>
            </body>

            <!-- RIGHT LEG -->
            <body name="right_hip_pitch_link" pos="0 -0.064452 -0.1027">
                <inertial pos="0.002741 -0.047791 -0.02606" quat="0.954862 -0.293964 0.0302556 -0.030122" mass="1.35"
                          diaginertia="0.00181517 0.00153422 0.00116212"/>
                <joint name="right_hip_pitch_joint" class="hip_pitch"/>
                <geom class="visual" material="black" mesh="right_hip_pitch_link"/>
                <body name="right_hip_roll_link" pos="0 -0.052 -0.030465" quat="0.996179 0 -0.0873386 0">
                    <inertial pos="0.029812 0.001045 -0.087934" quat="0.977808 1.97119e-05 0.205576 0.0403793" mass="1.52"
                              diaginertia="0.00254986 0.00241169 0.00148755"/>
                    <joint name="right_hip_roll_joint" class="hip_roll" range="-2.9671 0.5236"/>
                    <geom class="visual" mesh="right_hip_roll_link"/>
                    <geom name="right_thigh" class="collision" type="capsule" size="0.05" fromto="0.02 0 0 0.02 0 -0.2"/>
                    <body name="right_hip_yaw_link" pos="0.025001 0 -0.12412">
                        <inertial pos="-0.057709 0.010981 -0.15078" quat="0.751181 0.223482 0.15832 0.600598" mass="1.702"
                                  diaginertia="0.00776166 0.00717575 0.00160139"/>
                        <joint name="right_hip_yaw_joint" class="hip_yaw"/>
                        <geom class="visual" mesh="right_hip_yaw_link"/>
                        <body name="right_knee_link" pos="-0.078273 -0.0021489 -0.17734" quat="0.996179 0 0.0873386 0">
                            <inertial pos="0.005457 -0.003964 -0.12074" quat="0.923439 0.0345276 0.0116333 -0.382012" mass="1.932"
                                      diaginertia="0.011374 0.0112843 0.00146452"/>
                            <joint name="right_knee_joint" class="knee"/>
                            <geom class="visual" mesh="right_knee_link"/>
                            <geom name="right_shin" class="collision" type="capsule" size="0.04" fromto="0.02 0 0 0.02 0 -0.25"/>
                            <body name="right_ankle_pitch_link" pos="0 9.4445e-05 -0.30001">
                                <inertial pos="-0.007269 0 0.011137" quat="0.603053 0.369225 0.369225 0.603053" mass="0.074"
                                          diaginertia="1.89e-05 1.40805e-05 6.9195e-06"/>
                                <joint name="right_ankle_pitch_joint" class="ankle_pitch"/>
                                <geom class="visual" mesh="right_ankle_pitch_link"/>
                                <body name="right_ankle_roll_link" pos="0 0 -0.017558">
                                    <site name="right_foot" pos="0 0 0"/>
                                    <inertial pos="0.026505 0 -0.016425" quat="0.000481092 0.728482 0.000618967 0.685065" mass="0.608"
                                              diaginertia="0.00167218 0.0016161 0.000217621"/>
                                    <joint name="right_ankle_roll_joint" class="ankle_roll"/>
                                    <geom class="visual" material="black" mesh="right_ankle_roll_link"/>
                                    <geom name="right_foot1_collision" type="capsule" size="0.01" class="collision" fromto="0.1 -0.026 -0.025 0.05 -0.026 -0.025"/>
                                    <geom name="right_foot2_collision" type="capsule" size="0.008" class="collision" fromto="-0.044 -0.018 -0.025 0.123 -0.018 -0.025"/>
                                    <geom name="right_foot3_collision" type="capsule" size="0.01" class="collision" fromto="-0.052 -0.01 -0.025 0.13 -0.01 -0.025"/>
                                    <geom name="right_foot4_collision" type="capsule" size="0.01" class="collision" fromto="-0.054 0 -0.025 0.132 0 -0.025"/>
                                    <geom name="right_foot5_collision" type="capsule" size="0.01" class="collision" fromto="-0.052 0.01 -0.025 0.13 0.01 -0.025"/>
                                    <geom name="right_foot6_collision" type="capsule" size="0.008" class="collision" fromto="-0.044 0.018 -0.025 0.123 0.018 -0.025"/>
                                    <geom name="right_foot7_collision" type="capsule" size="0.01" class="collision" fromto="0.1 0.026 -0.025 0.05 0.026 -0.025"/>
                                </body>
                            </body>
                        </body>
                    </body>
                </body>
            </body>

            <!-- TORSO -->
            <body name="torso_link" pos="-0.0039635 0 0.054">
                <inertial pos="0.0034309 0.00025505 0.174524" quat="0.99988 0.000261157 0.0149809 -0.0038211" mass="9.842"
                          diaginertia="0.135151 0.123088 0.0327256"/>
                <joint name="waist_yaw_joint" class="waist_yaw"/>
                <geom class="visual" mesh="torso_link"/>
                <geom pos="0.0039635 0 -0.054" quat="1 0 0 0" class="visual" material="black" mesh="logo_link"/>
                <geom pos="0.0039635 0 -0.054" class="visual" material="black" mesh="head_link"/>
                <geom pos="0.0039635 0 -0.054" quat="1 0 0 0" class="visual" mesh="waist_support_link"/>

                <geom name="torso_collision1" class="collision" type="capsule" size="0.073" fromto="0.005 -0.032 .22 0.005 0.032 .22"/>
                <geom name="torso_collision2" class="collision" type="capsule" size="0.07" fromto="0.005 -0.028 .13 0.005 0.028 .13"/>
                <geom name="torso_collision3" class="collision" type="capsule" size="0.065" fromto="0.005 -0.02 .06 0.005 0.02 .06"/>
                <geom name="head_collision" class="collision" type="capsule" size="0.068" fromto="0.01 0 .41 0.01 0 .42"/>

                <site name="imu_in_torso" size="0.01" pos="-0.03959 -0.00224 0.14792"/>

                <!-- LEFT ARM -->
                <body name="left_shoulder_pitch_link" pos="0.0039563 0.10022 0.23778" quat="0.990264 0.139201 1.38722e-05 -9.86868e-05">
                    <inertial pos="0 0.035892 -0.011628" quat="0.654152 0.0130458 -0.326267 0.68225" mass="0.718"
                              diaginertia="0.000465864 0.000432842 0.000406394"/>
                    <joint name="left_shoulder_pitch_joint" class="shoulder_pitch"/>
                    <geom class="visual" mesh="left_shoulder_pitch_link"/>
                    <geom size="0.03 0.025" pos="0 0.04 -0.01" quat="0.707107 0 0.707107 0" type="cylinder" class="visual"/>
                    <body name="left_shoulder_roll_link" pos="0 0.038 -0.013831" quat="0.990268 -0.139172 0 0">
                        <inertial pos="-0.000227 0.00727 -0.063243" quat="0.701256 -0.0196223 -0.00710317 0.712604" mass="0.643"
                                  diaginertia="0.000691311 0.000618011 0.000388977"/>
                        <joint name="left_shoulder_roll_joint" range="-1.5882 2.2515" class="shoulder_roll"/>
                        <geom class="visual" mesh="left_shoulder_roll_link"/>
                        <geom size="0.03 0.015" pos="-0.004 0.006 -0.053" type="cylinder" class="visual"/>
                        <body name="left_shoulder_yaw_link" pos="0 0.00624 -0.1032">
                            <inertial pos="0.010773 -0.002949 -0.072009" quat="0.716879 -0.0964829 -0.0679942 0.687134"
                                      mass="0.734" diaginertia="0.00106187 0.00103217 0.000400661"/>
                            <joint name="left_shoulder_yaw_joint" class="shoulder_yaw"/>
                            <geom class="visual" mesh="left_shoulder_yaw_link"/>
                            <geom name="left_shoulder_yaw_collision" class="collision" type="capsule" size="0.035" fromto="0 0 -0.08 0 0 0.05"/>
                            <body name="left_elbow_link" pos="0.015783 0 -0.080518">
                                <inertial pos="0.064956 0.004454 -0.010062" quat="0.541765 0.636132 0.388821 0.388129" mass="0.6"
                                          diaginertia="0.000443035 0.000421612 0.000259353"/>
                                <joint name="left_elbow_joint" class="elbow"/>
                                <geom class="visual" mesh="left_elbow_link"/>
                                <geom name="left_elbow_collision" class="collision" type="capsule" size="0.035" fromto="-0.01 0 -0.01 0.12 0 -0.01"/>
                                <!-- 23DOF: wrist_roll connects directly to rubber hand -->
                                <body name="left_wrist_roll_rubber_hand" pos="0.1 0.00188791 -0.01">
                                    <inertial pos="0.107947 0.00163512 0.00202245" quat="0.494051 0.504265 0.48416 0.516933" mass="0.356929"
                                              diaginertia="0.00200292 0.0019426 0.000195232"/>
                                    <joint name="left_wrist_roll_joint" class="wrist_roll"/>
                                    <geom class="visual" mesh="left_wrist_roll_rubber_hand"/>
                                    <site name="left_palm" pos="0.15 0 0" size="0.01"/>
                                    <geom name="left_hand_collision" class="collision" type="capsule" size="0.05" fromto="0.05 0 0 0.15 0 0"/>
                                </body>
                            </body>
                        </body>
                    </body>
                </body>

                <!-- RIGHT ARM -->
                <body name="right_shoulder_pitch_link" pos="0.0039563 -0.10021 0.23778" quat="0.990264 -0.139201 1.38722e-05 9.86868e-05">
                    <inertial pos="0 -0.035892 -0.011628" quat="0.68225 -0.326267 0.0130458 0.654152" mass="0.718"
                              diaginertia="0.000465864 0.000432842 0.000406394"/>
                    <joint name="right_shoulder_pitch_joint" class="shoulder_pitch"/>
                    <geom class="visual" mesh="right_shoulder_pitch_link"/>
                    <geom size="0.03 0.025" pos="0 -0.04 -0.01" quat="0.707107 0 0.707107 0" type="cylinder" class="visual"/>
                    <body name="right_shoulder_roll_link" pos="0 -0.038 -0.013831" quat="0.990268 0.139172 0 0">
                        <inertial pos="-0.000227 -0.00727 -0.063243" quat="0.712604 -0.00710317 -0.0196223 0.701256"
                                  mass="0.643" diaginertia="0.000691311 0.000618011 0.000388977"/>
                        <joint name="right_shoulder_roll_joint" range="-2.2515 1.5882" class="shoulder_roll"/>
                        <geom class="visual" mesh="right_shoulder_roll_link"/>
                        <geom size="0.03 0.015" pos="-0.004 -0.006 -0.053" type="cylinder" class="visual"/>
                        <body name="right_shoulder_yaw_link" pos="0 -0.00624 -0.1032">
                            <inertial pos="0.010773 0.002949 -0.072009" quat="0.687134 -0.0679942 -0.0964829 0.716879"
                                      mass="0.734" diaginertia="0.00106187 0.00103217 0.000400661"/>
                            <joint name="right_shoulder_yaw_joint" class="shoulder_yaw"/>
                            <geom class="visual" mesh="right_shoulder_yaw_link"/>
                            <geom name="right_shoulder_yaw_collision" class="collision" type="capsule" size="0.035" fromto="0 0 -0.08 0 0 0.05"/>
                            <body name="right_elbow_link" pos="0.015783 0 -0.080518">
                                <inertial pos="0.064956 -0.004454 -0.010062" quat="0.388129 0.388821 0.636132 0.541765" mass="0.6"
                                          diaginertia="0.000443035 0.000421612 0.000259353"/>
                                <joint name="right_elbow_joint" class="elbow"/>
                                <geom class="visual" mesh="right_elbow_link"/>
                                <geom name="right_elbow_collision" class="collision" type="capsule" size="0.035" fromto="-0.01 0 -0.01 0.12 0 -0.01"/>
                                <!-- 23DOF: wrist_roll connects directly to rubber hand -->
                                <body name="right_wrist_roll_rubber_hand" pos="0.1 -0.00188791 -0.01">
                                    <inertial pos="0.107947 -0.00163512 0.00202245" quat="0.516933 0.48416 0.504265 0.494051" mass="0.356929"
                                              diaginertia="0.00200292 0.0019426 0.000195232"/>
                                    <joint name="right_wrist_roll_joint" class="wrist_roll"/>
                                    <geom class="visual" mesh="right_wrist_roll_rubber_hand"/>
                                    <site name="right_palm" pos="0.15 0 0" size="0.01"/>
                                    <geom name="right_hand_collision" class="collision" type="capsule" size="0.05" fromto="0.05 0 0 0.15 0 0"/>
                                </body>
                            </body>
                        </body>
                    </body>
                </body>
            </body>
        </body>
    </worldbody>

    <contact>
        <!-- left foot - floor -->
        <pair name="left_foot1_floor" geom1="left_foot1_collision" geom2="floor" solref="0.01 1" friction="0.8 0.8"/>
        <pair name="left_foot2_floor" geom1="left_foot2_collision" geom2="floor" solref="0.01 1" friction="0.8 0.8"/>
        <pair name="left_foot3_floor" geom1="left_foot3_collision" geom2="floor" solref="0.01 1" friction="0.8 0.8"/>
        <pair name="left_foot4_floor" geom1="left_foot4_collision" geom2="floor" solref="0.01 1" friction="0.8 0.8"/>
        <pair name="left_foot5_floor" geom1="left_foot5_collision" geom2="floor" solref="0.01 1" friction="0.8 0.8"/>
        <pair name="left_foot6_floor" geom1="left_foot6_collision" geom2="floor" solref="0.01 1" friction="0.8 0.8"/>
        <pair name="left_foot7_floor" geom1="left_foot7_collision" geom2="floor" solref="0.01 1" friction="0.8 0.8"/>
        <!-- right foot - floor -->
        <pair name="right_foot1_floor" geom1="right_foot1_collision" geom2="floor" solref="0.01 1" friction="0.8 0.8"/>
        <pair name="right_foot2_floor" geom1="right_foot2_collision" geom2="floor" solref="0.01 1" friction="0.8 0.8"/>
        <pair name="right_foot3_floor" geom1="right_foot3_collision" geom2="floor" solref="0.01 1" friction="0.8 0.8"/>
        <pair name="right_foot4_floor" geom1="right_foot4_collision" geom2="floor" solref="0.01 1" friction="0.8 0.8"/>
        <pair name="right_foot5_floor" geom1="right_foot5_collision" geom2="floor" solref="0.01 1" friction="0.8 0.8"/>
        <pair name="right_foot6_floor" geom1="right_foot6_collision" geom2="floor" solref="0.01 1" friction="0.8 0.8"/>
        <pair name="right_foot7_floor" geom1="right_foot7_collision" geom2="floor" solref="0.01 1" friction="0.8 0.8"/>
    </contact>

    <tendon>
        <fixed limited="true" range="-1e2 0.13708" solreflimit="0.003 1" solimplimit="0.99 0.999 0.0005 0 2">
            <joint joint="left_ankle_roll_joint" coef="-0.2618"/>
            <joint joint="left_ankle_pitch_joint" coef="0.2618"/>
        </fixed>
        <fixed limited="true" range="-1e2 0.13708" solreflimit="0.003 1" solimplimit="0.99 0.999 0.0005 0 2">
            <joint joint="left_ankle_roll_joint" coef="0.2618"/>
            <joint joint="left_ankle_pitch_joint" coef="0.2618"/>
        </fixed>
        <fixed limited="true" range="-1e2 0.22846" solreflimit="0.003 1" solimplimit="0.99 0.999 0.0005 0 2">
            <joint joint="left_ankle_roll_joint" coef="-0.14967"/>
            <joint joint="left_ankle_pitch_joint" coef="-0.2618 "/>
        </fixed>
        <fixed limited="true" range="-1e2 0.22846" solreflimit="0.003 1" solimplimit="0.99 0.999 0.0005 0 2">
            <joint joint="left_ankle_roll_joint" coef="0.14967"/>
            <joint joint="left_ankle_pitch_joint" coef="-0.2618"/>
        </fixed>
        <fixed limited="true" range="-1e2 0.13708" solreflimit="0.003 1" solimplimit="0.99 0.999 0.0005 0 2">
            <joint joint="right_ankle_roll_joint" coef="-0.2618"/>
            <joint joint="right_ankle_pitch_joint" coef="0.2618"/>
        </fixed>
        <fixed limited="true" range="-1e2 0.13708" solreflimit="0.003 1" solimplimit="0.99 0.999 0.0005 0 2">
            <joint joint="right_ankle_roll_joint" coef="0.2618"/>
            <joint joint="right_ankle_pitch_joint" coef="0.2618"/>
        </fixed>
        <fixed limited="true" range="-1e2 0.22846" solreflimit="0.003 1" solimplimit="0.99 0.999 0.0005 0 2">
            <joint joint="right_ankle_roll_joint" coef="-0.14967"/>
            <joint joint="right_ankle_pitch_joint" coef="-0.2618 "/>
        </fixed>
        <fixed limited="true" range="-1e2 0.22846" solreflimit="0.003 1" solimplimit="0.99 0.999 0.0005 0 2">
            <joint joint="right_ankle_roll_joint" coef="0.14967"/>
            <joint joint="right_ankle_pitch_joint" coef="-0.2618"/>
        </fixed>
    </tendon>

    <sensor>
        <framequat name="base_quat" objtype="site" objname="imu_in_pelvis"/>
        <gyro name="base_gyro" site="imu_in_pelvis"/>
        <accelerometer name="base_accel" site="imu_in_pelvis"/>

        <framepos name="frame_pos" objtype="site" objname="imu_in_pelvis"/>
        <framelinvel name="frame_vel" objtype="site" objname="imu_in_pelvis"/>
    </sensor>

    <visual>
        <headlight diffuse="0.6 0.6 0.6" ambient="0.3 0.3 0.3" specular="0 0 0"/>
        <rgba haze="0.15 0.25 0.35 1"/>
        <global azimuth="120" elevation="-20"/>
    </visual>

</mujoco>
